1734194553.6984801 [DEBUG] [launch.launch_context]: emitting event synchronously: 'launch.events.IncludeLaunchDescription'
1734194553.6990664 [INFO] [launch]: All log files can be found below /home/ros2_ws/.ros/log/2024-12-14-13-42-33-698040-sabrina-Inspiron-3501-5281
1734194553.6991456 [INFO] [launch]: Default logging verbosity is set to DEBUG
1734194553.7001832 [DEBUG] [launch]: processing event: '<launch.events.include_launch_description.IncludeLaunchDescription object at 0x7340359c7ee0>'
1734194553.7002943 [DEBUG] [launch]: processing event: '<launch.events.include_launch_description.IncludeLaunchDescription object at 0x7340359c7ee0>' ✓ '<launch.event_handlers.on_include_launch_description.OnIncludeLaunchDescription object at 0x7340366075b0>'
1734194553.7337539 [DEBUG] [launch]: An exception was raised in an async action/event
1734194553.7349746 [DEBUG] [launch]: Traceback (most recent call last):
  File "/opt/ros/humble/lib/python3.10/site-packages/launch/launch_description_sources/any_launch_file_utilities.py", line 54, in get_launch_description_from_any_launch_file
    return loader(launch_file_path)
  File "/opt/ros/humble/lib/python3.10/site-packages/launch/launch_description_sources/python_launch_file_utilities.py", line 68, in get_launch_description_from_python_launch_file
    return getattr(launch_file_module, 'generate_launch_description')()
  File "/home/ros2_ws/install/robot_description/share/robot_description/launch/gazebo.launch.py", line 17, in generate_launch_description
    robot_description_config = xacro.process_file(xacro_file)
  File "/opt/ros/humble/local/lib/python3.10/dist-packages/xacro/__init__.py", line 1096, in process_file
    doc = parse(None, input_file_name)
  File "/opt/ros/humble/local/lib/python3.10/dist-packages/xacro/__init__.py", line 1022, in parse
    return xml.dom.minidom.parse(inp)
  File "/usr/lib/python3.10/xml/dom/minidom.py", line 1990, in parse
    return expatbuilder.parse(file)
  File "/usr/lib/python3.10/xml/dom/expatbuilder.py", line 913, in parse
    result = builder.parseFile(file)
  File "/usr/lib/python3.10/xml/dom/expatbuilder.py", line 207, in parseFile
    parser.Parse(buffer, False)
xml.parsers.expat.ExpatError: unbound prefix: line 6, column 0

The above exception was the direct cause of the following exception:

Traceback (most recent call last):
  File "/opt/ros/humble/lib/python3.10/site-packages/launch/launch_service.py", line 336, in run_async
    raise completed_tasks_exceptions[0]
  File "/opt/ros/humble/lib/python3.10/site-packages/launch/launch_service.py", line 230, in _process_one_event
    await self.__process_event(next_event)
  File "/opt/ros/humble/lib/python3.10/site-packages/launch/launch_service.py", line 250, in __process_event
    visit_all_entities_and_collect_futures(entity, self.__context))
  File "/opt/ros/humble/lib/python3.10/site-packages/launch/utilities/visit_all_entities_and_collect_futures_impl.py", line 45, in visit_all_entities_and_collect_futures
    futures_to_return += visit_all_entities_and_collect_futures(sub_entity, context)
  File "/opt/ros/humble/lib/python3.10/site-packages/launch/utilities/visit_all_entities_and_collect_futures_impl.py", line 45, in visit_all_entities_and_collect_futures
    futures_to_return += visit_all_entities_and_collect_futures(sub_entity, context)
  File "/opt/ros/humble/lib/python3.10/site-packages/launch/utilities/visit_all_entities_and_collect_futures_impl.py", line 38, in visit_all_entities_and_collect_futures
    sub_entities = entity.visit(context)
  File "/opt/ros/humble/lib/python3.10/site-packages/launch/action.py", line 108, in visit
    return self.execute(context)
  File "/opt/ros/humble/lib/python3.10/site-packages/launch/actions/include_launch_description.py", line 148, in execute
    launch_description = self.__launch_description_source.get_launch_description(context)
  File "/opt/ros/humble/lib/python3.10/site-packages/launch/launch_description_source.py", line 84, in get_launch_description
    self._get_launch_description(self.__expanded_location)
  File "/opt/ros/humble/lib/python3.10/site-packages/launch/launch_description_sources/any_launch_description_source.py", line 53, in _get_launch_description
    return get_launch_description_from_any_launch_file(location)
  File "/opt/ros/humble/lib/python3.10/site-packages/launch/launch_description_sources/any_launch_file_utilities.py", line 57, in get_launch_description_from_any_launch_file
    raise InvalidLaunchFileError(extension, likely_errors=exceptions)
launch.invalid_launch_file_error.InvalidLaunchFileError: Caught multiple exceptions when trying to load file of format [py]:
 - ExpatError: unbound prefix: line 6, column 0
 - InvalidFrontendLaunchFileError: The launch file may have a syntax error, or its format is unknown

1734194553.7351222 [ERROR] [launch]: Caught exception in launch (see debug for traceback): Caught multiple exceptions when trying to load file of format [py]:
 - ExpatError: unbound prefix: line 6, column 0
 - InvalidFrontendLaunchFileError: The launch file may have a syntax error, or its format is unknown
1734194553.7351983 [DEBUG] [launch.launch_context]: emitting event: 'launch.events.Shutdown'
1734194553.7355022 [DEBUG] [launch]: processing event: '<launch.events.shutdown.Shutdown object at 0x7340359c4520>'
1734194553.7355764 [DEBUG] [launch]: processing event: '<launch.events.shutdown.Shutdown object at 0x7340359c4520>' ✓ '<launch.event_handlers.on_shutdown.OnShutdown object at 0x734036605cf0>'
